Workbook
Name 학교명목록: [1]학교정보!$E$2:$E$791

Sheet 기초자료입력
A1: 기초자료 입력 (공통 C-01~C-06 / 사업 B-01~B-07 / 문서별 D-01~D-05 / 반복 R-01~R-07) | G1: 불러온 레코드 순번 | H1: 2 | T1: 빠른 출력 선택 (서식선택_출력과 실시간 연동)
H2: 불러올 레코드 선택:
B3: 1. 공통 정보 (C)
A4: C-01 | B4: 학교명 * | C4: 전주고등학교 | E4: 학교 주소(자동) | F4: =IFERROR(INDEX([1]학교정보!$F$2:$F$791,MATCH($C$4,[1]학교정보!$E$2:$E$791,0)),"") -> 전주시 완산구 권삼득로 2 | T4: 선택 | U4: Form ID | V4: 서식명 | W4: 보기
A5: C-02 | B5: 학년도 * | C5: 2026 | E5: 학교 전화(자동) | F5: =IFERROR(INDEX([1]학교정보!$G$2:$G$791,MATCH($C$4,[1]학교정보!$E$2:$E$791,0)),"") -> 285-0212 | U5: =[1]서식선택_출력!B5 -> F-001 | V5: =[1]서식선택_출력!C5 -> 교복선정위원회 구성 기안
A6: C-03 | B6: 담당부서 | C6: 행정실 | U6: =[1]서식선택_출력!B6 -> F-002 | V6: =[1]서식선택_출력!C6 -> 위원 수락 및 확인서
A7: C-04 | B7: 담당자 직위 | C7: 주무관 | U7: =[2]서식선택_출력!B7 -> F-003 | V7: =[2]서식선택_출력!C7 -> 위원 청렴 및 보안 서약서
A8: C-05 | B8: 문서 발행일 | C8: 46023 | U8: =[2]서식선택_출력!B8 -> F-004 | V8: =[2]서식선택_출력!C8 -> 구매 추진 계획 수립
A9: C-06 | B9: 문서번호 | C9: 전주고-24244(26.1.1.) | U9: =[2]서식선택_출력!B9 -> F-005 | V9: =[2]서식선택_출력!C9 -> 구매 추진 계획안
A10: C-08 | B10: 담당자 성명 | C10: 윤호 | D10: C-07 | E10: 교장 성명(결재권자) | F10: 김호 | U10: =[2]서식선택_출력!B10 -> F-006 | V10: =[2]서식선택_출력!C10 -> 학교운영위원회 심의(안)
B11: 2. 사업 정보 (B) | U11: =[2]서식선택_출력!B11 -> F-007 | V11: =[2]서식선택_출력!C11 -> 교복구매 구매 요청
A12: B-01 | B12: 구매명 * | C12: 전주고 교복구매건 | U12: =[2]서식선택_출력!B12 -> F-008 | V12: =[2]서식선택_출력!C12 -> 교복 사양서
A13: B-02 | B13: 구매 학년 | C13: 1 | U13: =[2]서식선택_출력!B13 -> F-009 | V13: =[2]서식선택_출력!C13 -> 기초금액 및 계약방법 결정
A14: B-03 | B14: 계약방식 (계약방법안내에서 검토 후 반영) | C14: 일반경쟁입찰 | U14: =[2]서식선택_출력!B14 -> F-010 | V14: =[2]서식선택_출력!C14 -> 사전규격공개 기안문
A15: B-04 | B15: 기초금액(원) | C15: 20000000 | U15: =[2]서식선택_출력!B15 -> F-011 | V15: =[2]서식선택_출력!C15 -> 교복 학교주관구매 입찰 공고
A16: B-05 | B16: 예정수량 | C16: 200 | U16: =[2]서식선택_출력!B16 -> F-012 | V16: =[2]서식선택_출력!C16 -> 계약 특수조건
A17: B-06 | B17: 납품기한 | C17: 46388 | U17: =[2]서식선택_출력!B17 -> F-013 | V17: =[2]서식선택_출력!C17 -> 교복 디자인 및 규격서
A18: B-07 | B18: 제출기한 | C18: 46388 | U18: =[2]서식선택_출력!B18 -> F-014 | V18: =[2]서식선택_출력!C18 -> 제안서 평가항목 및 배점기준
U19: =[2]서식선택_출력!B19 -> F-015 | V19: =[2]서식선택_출력!C19 -> 정량적 평가
B20: 3. 문서별 정보 (D) — 서식 공통 기본값 | U20: =[2]서식선택_출력!B20 -> F-016 | V20: =[2]서식선택_출력!C20 -> 정성적 평가
A21: D-01 | B21: 수신 | U21: =[2]서식선택_출력!B21 -> F-017 | V21: =[2]서식선택_출력!C21 -> 제출서류 자기확인서
A22: D-02 | B22: 제목 * | C22: 전주고 교복구매건 | U22: =[2]서식선택_출력!B22 -> F-018 | V22: =[2]서식선택_출력!C22 -> 정량적 평가 자기 평점표
A23: D-03 | B23: 관련문서 | C23: 전주고-24244(26.1.1.) | U23: =[2]서식선택_출력!B23 -> F-019 | V23: =[2]서식선택_출력!C23 -> 입찰참가신청서
A24: D-04 | B24: 붙임 목록 | U24: =[2]서식선택_출력!B24 -> F-020 | V24: =[2]서식선택_출력!C24 -> 입찰 참가 신고서
A25: D-05 | B25: 안내문 본문 | U25: =[2]서식선택_출력!B25 -> F-021 | V25: =[2]서식선택_출력!C25 -> 교복 납품 제안서
U26: =[2]서식선택_출력!B26 -> F-022 | V26: =[2]서식선택_출력!C26 -> 교복 납품 실적표
B27: 4. 품목 반복행 (R-04 품목명 / R-05 수량 / R-06 단가 / K-01 금액 자동계산) — F-024 등에서 사용 | U27: =[2]서식선택_출력!B27 -> F-023 | V27: =[2]서식선택_출력!C27 -> 교복 제조 사양서
B28: 품목명 | C28: 수량 | D28: 단가(원) | E28: 금액(자동, K-01) | U28: =[2]서식선택_출력!B28 -> F-024 | V28: =[2]서식선택_출력!C28 -> 품목별 단가 비율표
B29: 상의 | C29: 200 | D29: 50000 | E29: =IF(AND(B29<>"",C29<>"",D29<>""),C29*D29,"") -> 10000000 | U29: =[2]서식선택_출력!B29 -> F-025 | V29: =[2]서식선택_출력!C29 -> 교복 A/S 계획서
B30: 하의 | C30: 200 | D30: 50000 | E30: =IF(AND(B30<>"",C30<>"",D30<>""),C30*D30,"") -> 10000000 | U30: =[2]서식선택_출력!B30 -> F-026 | V30: =[2]서식선택_출력!C30 -> 소비자 불만 처리 계획
E31: =IF(AND(B31<>"",C31<>"",D31<>""),C31*D31,"") | U31: =[2]서식선택_출력!B31 -> F-027 | V31: =[2]서식선택_출력!C31 -> 위임장
E32: =IF(AND(B32<>"",C32<>"",D32<>""),C32*D32,"") | U32: =[2]서식선택_출력!B32 -> F-028 | V32: =[2]서식선택_출력!C32 -> 서약서
E33: =IF(AND(B33<>"",C33<>"",D33<>""),C33*D33,"") | U33: =[2]서식선택_출력!B33 -> F-029 | V33: =[2]서식선택_출력!C33 -> 개인정보제공 동의서
E34: =IF(AND(B34<>"",C34<>"",D34<>""),C34*D34,"") | U34: =[2]서식선택_출력!B34 -> F-030 | V34: =[2]서식선택_출력!C34 -> 청렴계약 이행서약서
E35: =IF(AND(B35<>"",C35<>"",D35<>""),C35*D35,"") | U35: =[2]서식선택_출력!B35 -> F-031 | V35: =[2]서식선택_출력!C35 -> 교복 품목별 금액표
E36: =IF(AND(B36<>"",C36<>"",D36<>""),C36*D36,"") | U36: =[2]서식선택_출력!B36 -> F-032 | V36: =[2]서식선택_출력!C36 -> 제안서 접수 결과
E37: =IF(AND(B37<>"",C37<>"",D37<>""),C37*D37,"") | U37: =[2]서식선택_출력!B37 -> F-033 | V37: =[2]서식선택_출력!C37 -> 제안서 접수대장
E38: =IF(AND(B38<>"",C38<>"",D38<>""),C38*D38,"") | U38: =[2]서식선택_출력!B38 -> F-034 | V38: =[2]서식선택_출력!C38 -> 제안서 평가위원회 개최
B39: 합계 (K-02) | E39: =SUM(E29:E38) -> 20000000 | U39: =[2]서식선택_출력!B39 -> F-035 | V39: =[2]서식선택_출력!C39 -> 제안서 정량평가 결과
U40: =[2]서식선택_출력!B40 -> F-036 | V40: =[2]서식선택_출력!C40 -> 제안서 평가 결과
...

Sheet Sheet1
